root - 27-Sep-23 02:13:41 - ERROR - Internal Server Error!!!: Traceback (most recent call last):
  File "/usr/local/lib/python3.11/site-packages/rest_framework/views.py", line 506, in dispatch
    response = handler(request, *args, **kwargs)
               ^^^^^^^^^^^^^^^^^^^^^^^^^^^^^^^^^
  File "/usr/local/lib/python3.11/site-packages/rest_framework/generics.py", line 199, in get
    return self.list(request, *args, **kwargs)
           ^^^^^^^^^^^^^^^^^^^^^^^^^^^^^^^^^^^
  File "/usr/local/lib/python3.11/site-packages/rest_framework/mixins.py", line 38, in list
    queryset = self.filter_queryset(self.get_queryset())
                                    ^^^^^^^^^^^^^^^^^^^
  File "/medicalapp/hrecords/views.py", line 21, in get_queryset
    raise Exception("Annoying Error!!")
Exception: Annoying Error!!

root - 27-Sep-23 02:13:41 - ERROR - Internal Server Error!!!: <JsonResponse status_code=500, "application/json">
django.request - 27-Sep-23 02:13:41 - ERROR - Not Implemented: /api/v1.0/records/
medicalapp - 2023-09-27 02:19:07,895 - WARNING - This is a warning
medicalapp - 2023-09-27 02:19:07,896 - ERROR - This is an error
django.utils.autoreload - 27-Sep-23 02:45:36 - INFO - /medicalapp/manage.py changed, reloading.
medicalapp - 2023-09-27 02:56:56,754 - WARNING - This is a warning
medicalapp - 2023-09-27 02:56:56,760 - ERROR - This is an error
drf_yasg.inspectors.base - 27-Sep-23 02:57:06 - WARNING - view's RecordDetailAPIView raised exception during schema generation; use `getattr(self, 'swagger_fake_view', False)` to detect and short-circuit this
Traceback (most recent call last):
  File "/usr/local/lib/python3.11/site-packages/drf_yasg/inspectors/base.py", line 42, in call_view_method
    return view_method()
           ^^^^^^^^^^^^^
  File "/medicalapp/hrecords/views.py", line 53, in get_queryset
    urlparam: dict = URLParams.model_validate(self.kwargs).model_dump()
                     ^^^^^^^^^^^^^^^^^^^^^^^^^^^^^^^^^^^^^
  File "/usr/local/lib/python3.11/site-packages/pydantic/main.py", line 503, in model_validate
    return cls.__pydantic_validator__.validate_python(
           ^^^^^^^^^^^^^^^^^^^^^^^^^^^^^^^^^^^^^^^^^^^
pydantic_core._pydantic_core.ValidationError: 1 validation error for URLParams
pk
  Field required [type=missing, input_value={}, input_type=dict]
    For further information visit https://errors.pydantic.dev/2.4/v/missing
django.utils.autoreload - 27-Sep-23 03:20:02 - INFO - /medicalapp/hrecords/views.py changed, reloading.
medicalapp - 2023-09-27 03:20:07,605 - WARNING - This is a warning
medicalapp - 2023-09-27 03:20:07,607 - ERROR - This is an error
django.utils.autoreload - 27-Sep-23 03:20:15 - INFO - /medicalapp/medicalapp/settings.py changed, reloading.
medicalapp - 2023-09-27 03:20:19,783 - WARNING - This is a warning
medicalapp - 2023-09-27 03:20:19,784 - ERROR - This is an error
medicalapp - 2023-09-27 04:20:36,583 - WARNING - This is a warning
medicalapp - 2023-09-27 04:20:36,583 - ERROR - This is an error
django.utils.autoreload - 27-Sep-23 03:23:21 - INFO - /medicalapp/users/migrations/0001_initial.py changed, reloading.
medicalapp - 2023-09-27 03:23:28,843 - WARNING - This is a warning
medicalapp - 2023-09-27 03:23:28,846 - ERROR - This is an error
medicalapp - 2023-09-27 04:28:25,554 - WARNING - This is a warning
medicalapp - 2023-09-27 04:28:25,554 - ERROR - This is an error
medicalapp - 2023-09-27 04:29:02,641 - WARNING - This is a warning
medicalapp - 2023-09-27 04:29:02,641 - ERROR - This is an error
medicalapp - 2023-09-27 04:30:21,897 - WARNING - This is a warning
medicalapp - 2023-09-27 04:30:21,898 - ERROR - This is an error
medicalapp - 2023-09-27 04:30:36,637 - WARNING - This is a warning
medicalapp - 2023-09-27 04:30:36,637 - ERROR - This is an error
medicalapp - 2023-09-27 04:31:09,542 - WARNING - This is a warning
medicalapp - 2023-09-27 04:31:09,542 - ERROR - This is an error
medicalapp - 2023-09-27 04:33:09,903 - WARNING - This is a warning
medicalapp - 2023-09-27 04:33:09,904 - ERROR - This is an error
medicalapp - 2023-09-27 04:36:50,316 - WARNING - This is a warning
medicalapp - 2023-09-27 04:36:50,316 - ERROR - This is an error
medicalapp - 2023-09-27 04:38:45,323 - WARNING - This is a warning
medicalapp - 2023-09-27 04:38:45,323 - ERROR - This is an error
medicalapp - 2023-09-27 04:39:32,013 - WARNING - This is a warning
medicalapp - 2023-09-27 04:39:32,013 - ERROR - This is an error
medicalapp - 2023-09-27 04:40:38,324 - WARNING - This is a warning
medicalapp - 2023-09-27 04:40:38,324 - ERROR - This is an error
medicalapp - 2023-09-27 04:41:30,220 - WARNING - This is a warning
medicalapp - 2023-09-27 04:41:30,220 - ERROR - This is an error
medicalapp - 2023-09-27 04:43:09,445 - WARNING - This is a warning
medicalapp - 2023-09-27 04:43:09,446 - ERROR - This is an error
medicalapp - 2023-09-27 04:43:34,576 - WARNING - This is a warning
medicalapp - 2023-09-27 04:43:34,576 - ERROR - This is an error
medicalapp - 2023-09-27 04:44:10,901 - WARNING - This is a warning
medicalapp - 2023-09-27 04:44:10,901 - ERROR - This is an error
django.utils.autoreload - 27-Sep-23 03:45:12 - INFO - /medicalapp/medicalapp/logger.py changed, reloading.
django.utils.autoreload - 27-Sep-23 03:47:28 - INFO - /medicalapp/medicalapp/settings.py changed, reloading.
django.utils.autoreload - 27-Sep-23 03:50:00 - INFO - /medicalapp/medicalapp/errorhandler.py changed, reloading.
django.request - 27-Sep-23 04:12:05 - WARNING - Bad Request: /api/v1.0/auth/login
django.request - 27-Sep-23 06:41:34 - WARNING - Bad Request: /api/v1.0/auth/login
django.request - 27-Sep-23 06:41:47 - WARNING - Bad Request: /api/v1.0/auth/register
django.request - 27-Sep-23 06:42:18 - WARNING - Bad Request: /api/v1.0/auth/login
django.utils.autoreload - 27-Sep-23 06:57:55 - INFO - /medicalapp/medicalapp/settings.py changed, reloading.
django.utils.autoreload - 27-Sep-23 07:02:16 - INFO - /medicalapp/medicalapp/settings.py changed, reloading.
django.request - 27-Sep-23 07:32:18 - WARNING - Unprocessable Entity: /api/v1.0/auth/register
django.request - 27-Sep-23 07:45:30 - WARNING - Unauthorized: /api/v1.0/auth/logout
django.request - 27-Sep-23 07:52:19 - WARNING - Bad Request: /api/v1.0/auth/login
django.utils.autoreload - 27-Sep-23 07:54:33 - INFO - /medicalapp/medicalapp/errorhandler.py changed, reloading.
django.utils.autoreload - 27-Sep-23 07:56:06 - INFO - /medicalapp/users/views.py changed, reloading.
django.utils.autoreload - 27-Sep-23 07:56:42 - INFO - /medicalapp/users/views.py changed, reloading.
django.utils.autoreload - 27-Sep-23 07:57:51 - INFO - /medicalapp/users/urls.py changed, reloading.
django.utils.autoreload - 27-Sep-23 07:58:00 - INFO - /medicalapp/users/urls.py changed, reloading.
django.request - 27-Sep-23 07:58:17 - ERROR - Internal Server Error: /api/v1.0/auth/change-password
Traceback (most recent call last):
  File "/usr/local/lib/python3.11/site-packages/rest_framework/views.py", line 506, in dispatch
    response = handler(request, *args, **kwargs)
               ^^^^^^^^^^^^^^^^^^^^^^^^^^^^^^^^^
  File "/usr/local/lib/python3.11/site-packages/rest_framework/views.py", line 167, in http_method_not_allowed
    raise exceptions.MethodNotAllowed(request.method)
rest_framework.exceptions.MethodNotAllowed: Method "PUT" not allowed.

During handling of the above exception, another exception occurred:

Traceback (most recent call last):
  File "/usr/local/lib/python3.11/site-packages/django/core/handlers/exception.py", line 55, in inner
    response = get_response(request)
               ^^^^^^^^^^^^^^^^^^^^^
  File "/usr/local/lib/python3.11/site-packages/django/core/handlers/base.py", line 197, in _get_response
    response = wrapped_callback(request, *callback_args, **callback_kwargs)
               ^^^^^^^^^^^^^^^^^^^^^^^^^^^^^^^^^^^^^^^^^^^^^^^^^^^^^^^^^^^^
  File "/usr/local/lib/python3.11/site-packages/django/views/decorators/csrf.py", line 56, in wrapper_view
    return view_func(*args, **kwargs)
           ^^^^^^^^^^^^^^^^^^^^^^^^^^
  File "/usr/local/lib/python3.11/site-packages/django/views/generic/base.py", line 104, in view
    return self.dispatch(request, *args, **kwargs)
           ^^^^^^^^^^^^^^^^^^^^^^^^^^^^^^^^^^^^^^^
  File "/usr/local/lib/python3.11/site-packages/rest_framework/views.py", line 509, in dispatch
    response = self.handle_exception(exc)
               ^^^^^^^^^^^^^^^^^^^^^^^^^^
  File "/usr/local/lib/python3.11/site-packages/rest_framework/views.py", line 466, in handle_exception
    response = exception_handler(exc, context)
               ^^^^^^^^^^^^^^^^^^^^^^^^^^^^^^^
  File "/medicalapp/medicalapp/errorhandler.py", line 38, in global_exception_handler
    {"error": {"message": exc.detail.get("message")}},
                          ^^^^^^^^^^^^^^
AttributeError: 'ErrorDetail' object has no attribute 'get'
root - 27-Sep-23 07:58:17 - ERROR - Internal Server Error!!!: <HttpResponse status_code=500, "text/html; charset=utf-8">
django.request - 27-Sep-23 07:58:17 - ERROR - Not Implemented: /api/v1.0/auth/change-password
django.utils.autoreload - 27-Sep-23 08:00:24 - INFO - /medicalapp/medicalapp/errorhandler.py changed, reloading.
django.request - 27-Sep-23 08:00:30 - WARNING - Method Not Allowed: /api/v1.0/auth/change-password
django.request - 27-Sep-23 08:00:46 - WARNING - Method Not Allowed: /api/v1.0/auth/change-password
django.utils.autoreload - 27-Sep-23 08:01:23 - INFO - /medicalapp/users/views.py changed, reloading.
django.request - 27-Sep-23 08:01:28 - ERROR - Internal Server Error: /api/v1.0/auth/change-password
Traceback (most recent call last):
  File "/usr/local/lib/python3.11/site-packages/django/core/handlers/exception.py", line 55, in inner
    response = get_response(request)
               ^^^^^^^^^^^^^^^^^^^^^
  File "/usr/local/lib/python3.11/site-packages/django/core/handlers/base.py", line 197, in _get_response
    response = wrapped_callback(request, *callback_args, **callback_kwargs)
               ^^^^^^^^^^^^^^^^^^^^^^^^^^^^^^^^^^^^^^^^^^^^^^^^^^^^^^^^^^^^
  File "/usr/local/lib/python3.11/site-packages/django/views/decorators/csrf.py", line 56, in wrapper_view
    return view_func(*args, **kwargs)
           ^^^^^^^^^^^^^^^^^^^^^^^^^^
  File "/usr/local/lib/python3.11/site-packages/django/views/generic/base.py", line 104, in view
    return self.dispatch(request, *args, **kwargs)
           ^^^^^^^^^^^^^^^^^^^^^^^^^^^^^^^^^^^^^^^
  File "/usr/local/lib/python3.11/site-packages/rest_framework/views.py", line 511, in dispatch
    self.response = self.finalize_response(request, response, *args, **kwargs)
                    ^^^^^^^^^^^^^^^^^^^^^^^^^^^^^^^^^^^^^^^^^^^^^^^^^^^^^^^^^^
  File "/usr/local/lib/python3.11/site-packages/rest_framework/views.py", line 423, in finalize_response
    assert isinstance(response, HttpResponseBase), (
AssertionError: Expected a `Response`, `HttpResponse` or `HttpStreamingResponse` to be returned from the view, but received a `<class 'NoneType'>`
root - 27-Sep-23 08:01:28 - ERROR - Internal Server Error!!!: <HttpResponse status_code=500, "text/html; charset=utf-8">
django.request - 27-Sep-23 08:01:28 - ERROR - Not Implemented: /api/v1.0/auth/change-password
django.request - 27-Sep-23 08:03:28 - ERROR - Internal Server Error: /api/v1.0/auth/change-password
Traceback (most recent call last):
  File "/usr/local/lib/python3.11/site-packages/django/core/handlers/exception.py", line 55, in inner
    response = get_response(request)
               ^^^^^^^^^^^^^^^^^^^^^
  File "/usr/local/lib/python3.11/site-packages/django/core/handlers/base.py", line 197, in _get_response
    response = wrapped_callback(request, *callback_args, **callback_kwargs)
               ^^^^^^^^^^^^^^^^^^^^^^^^^^^^^^^^^^^^^^^^^^^^^^^^^^^^^^^^^^^^
  File "/usr/local/lib/python3.11/site-packages/django/views/decorators/csrf.py", line 56, in wrapper_view
    return view_func(*args, **kwargs)
           ^^^^^^^^^^^^^^^^^^^^^^^^^^
  File "/usr/local/lib/python3.11/site-packages/django/views/generic/base.py", line 104, in view
    return self.dispatch(request, *args, **kwargs)
           ^^^^^^^^^^^^^^^^^^^^^^^^^^^^^^^^^^^^^^^
  File "/usr/local/lib/python3.11/site-packages/rest_framework/views.py", line 511, in dispatch
    self.response = self.finalize_response(request, response, *args, **kwargs)
                    ^^^^^^^^^^^^^^^^^^^^^^^^^^^^^^^^^^^^^^^^^^^^^^^^^^^^^^^^^^
  File "/usr/local/lib/python3.11/site-packages/rest_framework/views.py", line 423, in finalize_response
    assert isinstance(response, HttpResponseBase), (
AssertionError: Expected a `Response`, `HttpResponse` or `HttpStreamingResponse` to be returned from the view, but received a `<class 'NoneType'>`
root - 27-Sep-23 08:03:28 - ERROR - Internal Server Error!!!: <HttpResponse status_code=500, "text/html; charset=utf-8">
django.request - 27-Sep-23 08:03:28 - ERROR - Not Implemented: /api/v1.0/auth/change-password
django.utils.autoreload - 27-Sep-23 08:03:39 - INFO - /medicalapp/users/views.py changed, reloading.
django.utils.autoreload - 27-Sep-23 08:05:49 - INFO - /medicalapp/users/views.py changed, reloading.
django.utils.autoreload - 27-Sep-23 08:06:14 - INFO - /medicalapp/users/views.py changed, reloading.
django.request - 27-Sep-23 08:06:22 - WARNING - Bad Request: /api/v1.0/auth/change-password
django.request - 27-Sep-23 08:06:51 - WARNING - Bad Request: /api/v1.0/auth/login
django.request - 27-Sep-23 08:07:00 - WARNING - Bad Request: /api/v1.0/auth/login
django.request - 27-Sep-23 08:07:45 - WARNING - Bad Request: /api/v1.0/auth/login
django.request - 27-Sep-23 08:10:01 - WARNING - Unauthorized: /api/v1.0/auth/token-refresh/
django.utils.autoreload - 27-Sep-23 08:18:51 - INFO - /medicalapp/hrecords/views.py changed, reloading.
django.utils.autoreload - 27-Sep-23 08:20:21 - INFO - /medicalapp/medicalapp/urls.py changed, reloading.
django.request - 27-Sep-23 08:20:55 - ERROR - Internal Server Error: /api/v1.0/records/create
Traceback (most recent call last):
  File "/usr/local/lib/python3.11/site-packages/django/core/handlers/exception.py", line 55, in inner
    response = get_response(request)
               ^^^^^^^^^^^^^^^^^^^^^
  File "/usr/local/lib/python3.11/site-packages/django/utils/deprecation.py", line 136, in __call__
    response = self.process_response(request, response)
               ^^^^^^^^^^^^^^^^^^^^^^^^^^^^^^^^^^^^^^^^
  File "/usr/local/lib/python3.11/site-packages/django/middleware/common.py", line 108, in process_response
    return self.response_redirect_class(self.get_full_path_with_slash(request))
                                        ^^^^^^^^^^^^^^^^^^^^^^^^^^^^^^^^^^^^^^
  File "/usr/local/lib/python3.11/site-packages/django/middleware/common.py", line 87, in get_full_path_with_slash
    raise RuntimeError(
RuntimeError: You called this URL via POST, but the URL doesn't end in a slash and you have APPEND_SLASH set. Django can't redirect to the slash URL while maintaining POST data. Change your form to point to localhost:8000/api/v1.0/records/create/ (note the trailing slash), or set APPEND_SLASH=False in your Django settings.
django.request - 27-Sep-23 08:21:29 - WARNING - Bad Request: /api/v1.0/records/4600/delete/
django.request - 27-Sep-23 08:49:29 - WARNING - Bad Request: /api/v1.0/auth/register
django.utils.autoreload - 27-Sep-23 08:53:48 - INFO - /medicalapp/medicalapp/urls.py changed, reloading.
django.utils.autoreload - 27-Sep-23 08:56:25 - INFO - /medicalapp/hrecords/views.py changed, reloading.
django.request - 27-Sep-23 09:05:06 - WARNING - Bad Request: /api/v1.0/auth/login
django.utils.autoreload - 27-Sep-23 09:05:58 - INFO - /medicalapp/medicalapp/errorhandler.py changed, reloading.
django.utils.autoreload - 27-Sep-23 09:06:11 - INFO - /medicalapp/medicalapp/errorhandler.py changed, reloading.
django.utils.autoreload - 27-Sep-23 09:06:36 - INFO - /medicalapp/medicalapp/errorhandler.py changed, reloading.
django.request - 27-Sep-23 09:06:45 - WARNING - Bad Request: /api/v1.0/records/create/
django.request - 27-Sep-23 09:07:03 - WARNING - Unauthorized: /api/v1.0/auth/change-password
django.request - 27-Sep-23 09:19:00 - WARNING - Not Found: /favicon.ico
django.request - 27-Sep-23 09:19:11 - WARNING - Not Found: /swagger/
django.request - 27-Sep-23 09:20:14 - WARNING - Not Found: /api/v2/products/
django.utils.autoreload - 27-Sep-23 09:53:01 - INFO - /medicalapp/medicalapp/errorhandler.py changed, reloading.
django.request - 27-Sep-23 09:53:20 - ERROR - Internal Server Error: /api/v1.0/auth/change-password
Traceback (most recent call last):
  File "/usr/local/lib/python3.11/site-packages/django/core/handlers/exception.py", line 55, in inner
    response = get_response(request)
               ^^^^^^^^^^^^^^^^^^^^^
  File "/usr/local/lib/python3.11/site-packages/django/core/handlers/base.py", line 197, in _get_response
    response = wrapped_callback(request, *callback_args, **callback_kwargs)
               ^^^^^^^^^^^^^^^^^^^^^^^^^^^^^^^^^^^^^^^^^^^^^^^^^^^^^^^^^^^^
  File "/usr/local/lib/python3.11/site-packages/django/views/decorators/csrf.py", line 56, in wrapper_view
    return view_func(*args, **kwargs)
           ^^^^^^^^^^^^^^^^^^^^^^^^^^
  File "/usr/local/lib/python3.11/site-packages/django/views/generic/base.py", line 104, in view
    return self.dispatch(request, *args, **kwargs)
           ^^^^^^^^^^^^^^^^^^^^^^^^^^^^^^^^^^^^^^^
  File "/usr/local/lib/python3.11/site-packages/rest_framework/views.py", line 509, in dispatch
    response = self.handle_exception(exc)
               ^^^^^^^^^^^^^^^^^^^^^^^^^^
  File "/usr/local/lib/python3.11/site-packages/rest_framework/views.py", line 469, in handle_exception
    self.raise_uncaught_exception(exc)
  File "/usr/local/lib/python3.11/site-packages/rest_framework/views.py", line 480, in raise_uncaught_exception
    raise exc
  File "/usr/local/lib/python3.11/site-packages/rest_framework/views.py", line 506, in dispatch
    response = handler(request, *args, **kwargs)
               ^^^^^^^^^^^^^^^^^^^^^^^^^^^^^^^^^
  File "/medicalapp/users/views.py", line 88, in post
    status=status.HTTP_204_CREATED,
           ^^^^^^^^^^^^^^^^^^^^^^^
AttributeError: module 'rest_framework.status' has no attribute 'HTTP_204_CREATED'
django.utils.autoreload - 27-Sep-23 09:54:29 - INFO - /medicalapp/users/views.py changed, reloading.
django.request - 27-Sep-23 09:54:35 - WARNING - Bad Request: /api/v1.0/auth/change-password
django.utils.autoreload - 27-Sep-23 09:55:10 - INFO - /medicalapp/users/views.py changed, reloading.
django.utils.autoreload - 27-Sep-23 09:55:39 - INFO - /medicalapp/users/views.py changed, reloading.
django.request - 27-Sep-23 09:55:46 - WARNING - Bad Request: /api/v1.0/auth/change-password
django.utils.autoreload - 27-Sep-23 09:55:56 - INFO - /medicalapp/users/views.py changed, reloading.
django.utils.autoreload - 27-Sep-23 09:56:07 - INFO - /medicalapp/users/views.py changed, reloading.
django.utils.autoreload - 27-Sep-23 09:56:17 - INFO - /medicalapp/users/views.py changed, reloading.
django.utils.autoreload - 27-Sep-23 09:56:27 - INFO - /medicalapp/users/views.py changed, reloading.
django.utils.autoreload - 27-Sep-23 09:56:38 - INFO - /medicalapp/users/views.py changed, reloading.
django.utils.autoreload - 27-Sep-23 09:56:44 - INFO - /medicalapp/users/views.py changed, reloading.
django.request - 27-Sep-23 09:57:29 - WARNING - Bad Request: /api/v1.0/auth/login
django.utils.autoreload - 27-Sep-23 09:59:25 - INFO - /medicalapp/medicalapp/errorhandler.py changed, reloading.
django.utils.autoreload - 27-Sep-23 09:59:36 - INFO - /medicalapp/medicalapp/errorhandler.py changed, reloading.
django.utils.autoreload - 27-Sep-23 09:59:46 - INFO - /medicalapp/medicalapp/errorhandler.py changed, reloading.
django.request - 27-Sep-23 09:59:56 - WARNING - Bad Request: /api/v1.0/auth/change-password
django.utils.autoreload - 27-Sep-23 10:06:52 - INFO - /medicalapp/medicalapp/errorhandler.py changed, reloading.
django.request - 27-Sep-23 10:07:07 - WARNING - Unprocessable Entity: /api/v1.0/records/create/
django.request - 27-Sep-23 10:11:08 - WARNING - Forbidden: /api/v1.0/records/1/update/
django.request - 27-Sep-23 10:12:18 - WARNING - Bad Request: /api/v1.0/records/2/delete/
